2023-06-02 17:07:42,187 INFO    ======================================================================
2023-06-02 17:07:42,188 INFO    Survey 351, for Aiuruoca, Minas Gerais
2023-06-02 17:07:42,190 INFO    Searching by bounding box, max_zoom=24
2023-06-02 17:07:42,222 INFO    ----------------------------------------------------------------------
2023-06-02 17:07:42,222 INFO    Rectangle calculated: [-44.529, -21.742, -44.766, -22.163]
2023-06-02 17:07:42,223 INFO    Searching rectangle: zoom factor = 0, node = []
2023-06-02 17:07:44,060 WARNING HTTP status 403 from web site: IP address blocked. Waiting 0.1 minutes.
2023-06-02 17:07:51,839 INFO    Page 01 returned 00 listings
2023-06-02 17:07:51,839 INFO    Final page of listings for this search
2023-06-02 17:07:51,839 INFO    Results: 1 pages, 0 new rooms
2023-06-02 17:07:51,841 INFO    Finishing survey 351, for Aiuruoca, Minas Gerais
2023-06-02 17:07:51,844 INFO    Initialing search by overall satisfactions
2023-06-02 17:07:51,847 INFO    0 results
2023-06-02 17:07:51,847 INFO    Updating status of super survey 88 to 3
2023-06-02 17:07:51,849 INFO    Updating status of super survey 88 to 41
2023-06-02 17:07:51,850 INFO    Selecting sublocalities from city
2023-06-02 17:07:51,914 INFO    Updating status of super survey 88 to 43
2023-06-02 17:07:51,915 INFO    Updating status of super survey 88 to 4
2023-06-02 17:07:51,917 INFO    Updating status of super survey 88 to 51
2023-06-02 17:07:51,919 INFO    Selecting routes from sublocality
2023-06-02 17:07:51,973 INFO    Updating status of super survey 88 to 53
2023-06-02 17:07:51,975 INFO    Updating status of super survey 88 to 5
2023-06-02 17:07:51,976 INFO    Updating status of super survey 88 to 6
2023-06-02 17:07:51,977 INFO    Updating status of super survey 88 to 7
2023-06-02 17:07:51,978 INFO    Updating status of super survey 0 to 11
2023-06-02 17:07:51,979 ERROR   Failed to update status of super survey 0 to 11
2023-06-02 17:07:53,528 WARNING Retrying (Retry(total=1, connect=None, read=None, redirect=None, status=None)) after connection broken by 'ReadTimeoutError("HTTPSConnectionPool(host='nominatim.openstreetmap.org', port=443): Read timed out. (read timeout=1)")': /search?q=Aiuruoca%2C+Minas+Gerais&format=json&limit=1
2023-06-02 17:07:55,561 WARNING Retrying (Retry(total=0, connect=None, read=None, redirect=None, status=None)) after connection broken by 'ConnectTimeoutError(<urllib3.connection.HTTPSConnection object at 0x00000268A4EDB410>, 'Connection to nominatim.openstreetmap.org timed out. (connect timeout=1)')': /search?q=Aiuruoca%2C+Minas+Gerais&format=json&limit=1
2023-06-02 17:07:57,587 ERROR   Exception in BoundingBox_from_geopy: exiting
Traceback (most recent call last):
  File "C:\Users\Usuario\AppData\Local\Programs\Python\Python311\Lib\site-packages\urllib3\connection.py", line 174, in _new_conn
    conn = connection.create_connection(
           ^^^^^^^^^^^^^^^^^^^^^^^^^^^^^
  File "C:\Users\Usuario\AppData\Local\Programs\Python\Python311\Lib\site-packages\urllib3\util\connection.py", line 95, in create_connection
    raise err
  File "C:\Users\Usuario\AppData\Local\Programs\Python\Python311\Lib\site-packages\urllib3\util\connection.py", line 85, in create_connection
    sock.connect(sa)
TimeoutError: timed out

During handling of the above exception, another exception occurred:

Traceback (most recent call last):
  File "C:\Users\Usuario\AppData\Local\Programs\Python\Python311\Lib\site-packages\urllib3\connectionpool.py", line 703, in urlopen
    httplib_response = self._make_request(
                       ^^^^^^^^^^^^^^^^^^^
  File "C:\Users\Usuario\AppData\Local\Programs\Python\Python311\Lib\site-packages\urllib3\connectionpool.py", line 386, in _make_request
    self._validate_conn(conn)
  File "C:\Users\Usuario\AppData\Local\Programs\Python\Python311\Lib\site-packages\urllib3\connectionpool.py", line 1042, in _validate_conn
    conn.connect()
  File "C:\Users\Usuario\AppData\Local\Programs\Python\Python311\Lib\site-packages\urllib3\connection.py", line 358, in connect
    self.sock = conn = self._new_conn()
                       ^^^^^^^^^^^^^^^^
  File "C:\Users\Usuario\AppData\Local\Programs\Python\Python311\Lib\site-packages\urllib3\connection.py", line 179, in _new_conn
    raise ConnectTimeoutError(
urllib3.exceptions.ConnectTimeoutError: (<urllib3.connection.HTTPSConnection object at 0x00000268A4EDB710>, 'Connection to nominatim.openstreetmap.org timed out. (connect timeout=1)')

During handling of the above exception, another exception occurred:

Traceback (most recent call last):
  File "C:\Users\Usuario\AppData\Local\Programs\Python\Python311\Lib\site-packages\requests\adapters.py", line 489, in send
    resp = conn.urlopen(
           ^^^^^^^^^^^^^
  File "C:\Users\Usuario\AppData\Local\Programs\Python\Python311\Lib\site-packages\urllib3\connectionpool.py", line 815, in urlopen
    return self.urlopen(
           ^^^^^^^^^^^^^
  File "C:\Users\Usuario\AppData\Local\Programs\Python\Python311\Lib\site-packages\urllib3\connectionpool.py", line 815, in urlopen
    return self.urlopen(
           ^^^^^^^^^^^^^
  File "C:\Users\Usuario\AppData\Local\Programs\Python\Python311\Lib\site-packages\urllib3\connectionpool.py", line 787, in urlopen
    retries = retries.increment(
              ^^^^^^^^^^^^^^^^^^
  File "C:\Users\Usuario\AppData\Local\Programs\Python\Python311\Lib\site-packages\urllib3\util\retry.py", line 592, in increment
    raise MaxRetryError(_pool, url, error or ResponseError(cause))
urllib3.exceptions.MaxRetryError: HTTPSConnectionPool(host='nominatim.openstreetmap.org', port=443): Max retries exceeded with url: /search?q=Aiuruoca%2C+Minas+Gerais&format=json&limit=1 (Caused by ConnectTimeoutError(<urllib3.connection.HTTPSConnection object at 0x00000268A4EDB710>, 'Connection to nominatim.openstreetmap.org timed out. (connect timeout=1)'))

During handling of the above exception, another exception occurred:

Traceback (most recent call last):
  File "C:\Users\Usuario\AppData\Local\Programs\Python\Python311\Lib\site-packages\geopy\adapters.py", line 457, in _request
    resp = self.session.get(url, timeout=timeout, headers=headers)
           ^^^^^^^^^^^^^^^^^^^^^^^^^^^^^^^^^^^^^^^^^^^^^^^^^^^^^^^
  File "C:\Users\Usuario\AppData\Local\Programs\Python\Python311\Lib\site-packages\requests\sessions.py", line 600, in get
    return self.request("GET", url, **kwargs)
           ^^^^^^^^^^^^^^^^^^^^^^^^^^^^^^^^^^
  File "C:\Users\Usuario\AppData\Local\Programs\Python\Python311\Lib\site-packages\requests\sessions.py", line 587, in request
    resp = self.send(prep, **send_kwargs)
           ^^^^^^^^^^^^^^^^^^^^^^^^^^^^^^
  File "C:\Users\Usuario\AppData\Local\Programs\Python\Python311\Lib\site-packages\requests\sessions.py", line 701, in send
    r = adapter.send(request, **kwargs)
        ^^^^^^^^^^^^^^^^^^^^^^^^^^^^^^^
  File "C:\Users\Usuario\AppData\Local\Programs\Python\Python311\Lib\site-packages\requests\adapters.py", line 553, in send
    raise ConnectTimeout(e, request=request)
requests.exceptions.ConnectTimeout: HTTPSConnectionPool(host='nominatim.openstreetmap.org', port=443): Max retries exceeded with url: /search?q=Aiuruoca%2C+Minas+Gerais&format=json&limit=1 (Caused by ConnectTimeoutError(<urllib3.connection.HTTPSConnection object at 0x00000268A4EDB710>, 'Connection to nominatim.openstreetmap.org timed out. (connect timeout=1)'))

During handling of the above exception, another exception occurred:

Traceback (most recent call last):
  File "C:\mono\mono\backend\airbnb_geocoding.py", line 421, in from_geopy
    location = geolocator.geocode((search_area))
               ^^^^^^^^^^^^^^^^^^^^^^^^^^^^^^^^^
  File "C:\Users\Usuario\AppData\Local\Programs\Python\Python311\Lib\site-packages\geopy\geocoders\nominatim.py", line 297, in geocode
    return self._call_geocoder(url, callback, timeout=timeout)
           ^^^^^^^^^^^^^^^^^^^^^^^^^^^^^^^^^^^^^^^^^^^^^^^^^^^
  File "C:\Users\Usuario\AppData\Local\Programs\Python\Python311\Lib\site-packages\geopy\geocoders\base.py", line 368, in _call_geocoder
    result = self.adapter.get_json(url, timeout=timeout, headers=req_headers)
             ^^^^^^^^^^^^^^^^^^^^^^^^^^^^^^^^^^^^^^^^^^^^^^^^^^^^^^^^^^^^^^^^
  File "C:\Users\Usuario\AppData\Local\Programs\Python\Python311\Lib\site-packages\geopy\adapters.py", line 447, in get_json
    resp = self._request(url, timeout=timeout, headers=headers)
           ^^^^^^^^^^^^^^^^^^^^^^^^^^^^^^^^^^^^^^^^^^^^^^^^^^^^
  File "C:\Users\Usuario\AppData\Local\Programs\Python\Python311\Lib\site-packages\geopy\adapters.py", line 469, in _request
    raise GeocoderUnavailable(message)
geopy.exc.GeocoderUnavailable: HTTPSConnectionPool(host='nominatim.openstreetmap.org', port=443): Max retries exceeded with url: /search?q=Aiuruoca%2C+Minas+Gerais&format=json&limit=1 (Caused by ConnectTimeoutError(<urllib3.connection.HTTPSConnection object at 0x00000268A4EDB710>, 'Connection to nominatim.openstreetmap.org timed out. (connect timeout=1)'))
